<?xml version="1.0" ?>
<!-- =================================================================================== -->
<!-- |    This document was autogenerated by xacro from workcell.xacro                 | -->
<!-- |    EDITING THIS FILE BY HAND IS NOT RECOMMENDED                                 | -->
<!-- =================================================================================== -->
<robot name="aimen_workcell" xmlns:xacro="http://ros.org/wiki/xacro">
  <!-- Robot cell -->
  <link name="world"/>
  <!-- Robot -->
  <!-- Robot -->
  <!-- link list -->
  <link name="base_link">
    <visual>
      <geometry>
        <mesh filename="package://aimen_abb/meshes/irb4400/visual/base_link.stl"/>
      </geometry>
      <material name="abb_orange">
        <color rgba="1 0.43 0 1"/>
      </material>
    </visual>
    <collision>
      <geometry>
        <mesh filename="package://aimen_abb/meshes/irb4400/collision/base_link.stl"/>
      </geometry>
      <material name="yellow">
        <color rgba="0 1 1 1"/>
      </material>
    </collision>
  </link>
  <link name="link_1">
    <visual>
      <geometry>
        <mesh filename="package://aimen_abb/meshes/irb4400/visual/link_1.stl"/>
      </geometry>
      <material name="abb_orange"/>
    </visual>
    <collision>
      <geometry>
        <mesh filename="package://aimen_abb/meshes/irb4400/collision/link_1.stl"/>
      </geometry>
      <material name="yellow"/>
    </collision>
  </link>
  <link name="link_2">
    <visual>
      <geometry>
        <mesh filename="package://aimen_abb/meshes/irb4400/visual/link_2.stl"/>
      </geometry>
      <material name="abb_orange"/>
    </visual>
    <collision>
      <geometry>
        <mesh filename="package://aimen_abb/meshes/irb4400/collision/link_2.stl"/>
      </geometry>
      <material name="yellow"/>
    </collision>
  </link>
  <link name="link_3">
    <visual>
      <geometry>
        <mesh filename="package://aimen_abb/meshes/irb4400/visual/link_3.stl"/>
      </geometry>
      <material name="abb_orange"/>
    </visual>
    <collision>
      <geometry>
        <mesh filename="package://aimen_abb/meshes/irb4400/collision/link_3.stl"/>
      </geometry>
      <material name="yellow"/>
    </collision>
  </link>
  <link name="link_4">
    <visual>
      <geometry>
        <mesh filename="package://aimen_abb/meshes/irb4400/visual/link_4.stl"/>
      </geometry>
      <material name="abb_orange"/>
    </visual>
    <collision>
      <geometry>
        <mesh filename="package://aimen_abb/meshes/irb4400/collision/link_4.stl"/>
      </geometry>
      <material name="yellow"/>
    </collision>
  </link>
  <link name="link_5">
    <visual>
      <geometry>
        <mesh filename="package://aimen_abb/meshes/irb4400/visual/link_5.stl"/>
      </geometry>
      <material name="abb_orange"/>
    </visual>
    <collision>
      <geometry>
        <mesh filename="package://aimen_abb/meshes/irb4400/collision/link_5.stl"/>
      </geometry>
      <material name="yellow"/>
    </collision>
  </link>
  <link name="link_6">
    <visual>
      <geometry>
        <mesh filename="package://aimen_abb/meshes/irb4400/visual/link_6.stl"/>
      </geometry>
      <material name="lt_black">
        <color rgba="0.3 0.3 0.3 1"/>
      </material>
    </visual>
    <collision>
      <geometry>
        <mesh filename="package://aimen_abb/meshes/irb4400/collision/link_6.stl"/>
      </geometry>
      <material name="yellow"/>
    </collision>
  </link>
  <link name="tool0"/>
  <!-- Parallelogram -->
  <link name="link_d1">
    <visual>
      <geometry>
        <mesh filename="package://aimen_abb/meshes/irb4400/visual/link_d1.stl"/>
      </geometry>
      <material name="abb_orange"/>
    </visual>
  </link>
  <link name="link_d2">
    <visual>
      <geometry>
        <mesh filename="package://aimen_abb/meshes/irb4400/visual/link_d2.stl"/>
      </geometry>
      <material name="abb_orange"/>
    </visual>
  </link>
  <link name="link_d3">
    <visual>
      <geometry>
        <mesh filename="package://aimen_abb/meshes/irb4400/visual/link_d3.stl"/>
      </geometry>
      <material name="abb_orange"/>
    </visual>
  </link>
  <link name="link_d4">
    <visual>
      <geometry>
        <mesh filename="package://aimen_abb/meshes/irb4400/visual/link_d4.stl"/>
      </geometry>
      <material name="abb_orange"/>
    </visual>
  </link>
  <!-- end of link list -->
  <!-- joint list -->
  <joint name="joint_1" type="revolute">
    <parent link="base_link"/>
    <child link="link_1"/>
    <origin rpy="0 0 0" xyz="0 0 0"/>
    <axis xyz="0 0 1"/>
    <limit effort="0" lower="-2.8798" upper="2.8798" velocity="2.6180"/>
  </joint>
  <joint name="joint_2" type="revolute">
    <parent link="link_1"/>
    <child link="link_2"/>
    <origin rpy="0 0 0" xyz="0.200 0 0.680"/>
    <axis xyz="0 1 0"/>
    <limit effort="0" lower="-1.2217" upper="1.6755" velocity="2.0944"/>
  </joint>
  <joint name="joint_3" type="revolute">
    <parent link="link_2"/>
    <child link="link_3"/>
    <origin rpy="0 0 0" xyz="0 0 0.890"/>
    <axis xyz="0 1 0"/>
    <limit effort="0" lower="-1.0472" upper="1.1345" velocity="2.0944"/>
  </joint>
  <joint name="joint_4" type="revolute">
    <parent link="link_3"/>
    <child link="link_4"/>
    <origin rpy="0 0 0" xyz="0 0 0.150"/>
    <axis xyz="1 0 0"/>
    <limit effort="0" lower="-3.4907" upper="3.4907" velocity="3.9270"/>
  </joint>
  <joint name="joint_5" type="revolute">
    <parent link="link_4"/>
    <child link="link_5"/>
    <origin rpy="0 0 0" xyz="0.880 0 0"/>
    <axis xyz="0 1 0"/>
    <limit effort="0" lower="-2.0944" upper="2.0944" velocity="2.3633"/>
  </joint>
  <joint name="joint_6" type="revolute">
    <parent link="link_5"/>
    <child link="link_6"/>
    <origin rpy="0 0 0" xyz="0 0 0"/>
    <axis xyz="1 0 0"/>
    <limit effort="0" lower="-6.9813" upper="6.9813" velocity="5.7596"/>
  </joint>
  <joint name="tool0" type="fixed">
    <parent link="link_6"/>
    <child link="tool0"/>
    <origin rpy="0 1.5708 0" xyz="0.140 0 0"/>
  </joint>
  <!-- Parallelogram -->
  <joint name="joint_d1" type="revolute">
    <parent link="link_3"/>
    <child link="link_d1"/>
    <origin rpy="0 0 0" xyz="-0.300 0 0"/>
    <axis xyz="0 1 0"/>
    <mimic joint="joint_3" multiplier="-1.0" offset="0.0"/>
    <limit effort="0" lower="-1.2217" upper="1.6755" velocity="2.0944"/>
  </joint>
  <joint name="joint_d2" type="revolute">
    <parent link="link_1"/>
    <child link="link_d2"/>
    <origin rpy="0 0 0" xyz="0.200 0 0.680"/>
    <axis xyz="0 1 0"/>
    <mimic joint="joint_2" multiplier="1.0" offset="0.0"/>
    <mimic joint="joint_3" multiplier="1.0" offset="0.0"/>
    <limit effort="0" lower="-1.2217" upper="1.6755" velocity="2.0944"/>
  </joint>
  <joint name="joint_d3" type="fixed">
    <parent link="link_1"/>
    <child link="link_d3"/>
    <origin rpy="0 0 0" xyz="0 0 0"/>
    <axis xyz="0 1 0"/>
    <mimic joint="joint_2" multiplier="0.5" offset="0.0"/>
    <limit effort="0" lower="-1.2217" upper="1.6755" velocity="2.0944"/>
  </joint>
  <joint name="joint_d4" type="fixed">
    <parent link="link_1"/>
    <child link="link_d4"/>
    <origin rpy="0 0 0" xyz="0 0 0"/>
    <axis xyz="0 1 0"/>
    <mimic joint="joint_2" multiplier="0.5" offset="0.0"/>
    <limit effort="0" lower="-1.2217" upper="1.6755" velocity="2.0944"/>
  </joint>
  <!-- end of joint list -->
  <joint name="irb4400" type="fixed">
    <parent link="world"/>
    <child link="base_link"/>
    <origin rpy="0 0 0" xyz="0 0 0.067"/>
  </joint>
  <!-- Robot table -->
  <link name="irbp_a250/base_link">
    <visual>
      <geometry>
        <mesh filename="package://aimen_workcell/meshes/irbp_a250/visual/irbp_a250_0.stl"/>
      </geometry>
      <material name="black">
        <color rgba="0.1 0.1 0.1 1"/>
      </material>
    </visual>
    <collision>
      <geometry>
        <mesh filename="package://aimen_workcell/meshes/irbp_a250/collision/irbp_a250_0.stl"/>
      </geometry>
      <material name="yellow">
        <color rgba="0 1 1 1"/>
      </material>
    </collision>
  </link>
  <link name="irbp_a250/link_1">
    <visual>
      <geometry>
        <mesh filename="package://aimen_workcell/meshes/irbp_a250/visual/irbp_a250_1.stl"/>
      </geometry>
      <material name="abb_orange">
        <color rgba="1 0.43 0 1"/>
      </material>
    </visual>
    <collision>
      <geometry>
        <mesh filename="package://aimen_workcell/meshes/irbp_a250/collision/irbp_a250_1.stl"/>
      </geometry>
      <material name="yellow"/>
    </collision>
  </link>
  <link name="irbp_a250/link_2">
    <visual>
      <geometry>
        <mesh filename="package://aimen_workcell/meshes/irbp_a250/visual/irbp_a250_2.stl"/>
      </geometry>
      <material name="abb_orange"/>
    </visual>
    <collision>
      <geometry>
        <mesh filename="package://aimen_workcell/meshes/irbp_a250/collision/irbp_a250_2.stl"/>
      </geometry>
      <material name="yellow"/>
    </collision>
  </link>
  <link name="irbp_a250/link_3">
    <visual>
      <geometry>
        <mesh filename="package://aimen_workcell/meshes/irbp_a250/visual/irbp_a250_3.stl"/>
      </geometry>
      <material name="abb_orange"/>
    </visual>
    <collision>
      <geometry>
        <mesh filename="package://aimen_workcell/meshes/irbp_a250/collision/irbp_a250_3.stl"/>
      </geometry>
      <material name="yellow"/>
    </collision>
  </link>
  <link name="irbp_a250/link_4">
    <visual>
      <geometry>
        <mesh filename="package://aimen_workcell/meshes/irbp_a250/visual/irbp_a250_4.stl"/>
      </geometry>
      <material name="black">
        <color rgba="0 0 0 1"/>
      </material>
    </visual>
    <collision>
      <geometry>
        <mesh filename="package://aimen_workcell/meshes/irbp_a250/collision/irbp_a250_4.stl"/>
      </geometry>
      <material name="yellow"/>
    </collision>
  </link>
  <link name="irbp_a250/tool0"/>
  <joint name="irbp_a250/joint1" type="fixed">
    <parent link="irbp_a250/base_link"/>
    <child link="irbp_a250/link_1"/>
    <origin rpy="0 0 0" xyz="0 0 0"/>
    <axis xyz="0 0 1"/>
  </joint>
  <joint name="irbp_a250/joint2" type="fixed">
    <!--"revolute"-->
    <parent link="irbp_a250/link_1"/>
    <child link="irbp_a250/link_2"/>
    <origin rpy="0 0 0" xyz="0 0 1.020"/>
    <axis xyz="1 0 0"/>
    <limit effort="100" lower="-3.1590" upper="3.1590" velocity="2.6180"/>
  </joint>
  <joint name="irbp_a250/joint3" type="fixed">
    <parent link="irbp_a250/link_2"/>
    <child link="irbp_a250/link_3"/>
    <origin rpy="0 0 0" xyz="0 0 0"/>
    <axis xyz="0 1 0"/>
  </joint>
  <joint name="irbp_a250/joint4" type="fixed">
    <!--"continuous"-->
    <parent link="irbp_a250/link_3"/>
    <child link="irbp_a250/link_4"/>
    <origin rpy="0 0 0" xyz="0 0 -0.120"/>
    <axis xyz="0 0 1"/>
    <limit effort="100" velocity="3.1416"/>
  </joint>
  <joint name="irbp_a250/tool0" type="fixed">
    <parent link="irbp_a250/link_4"/>
    <child link="irbp_a250/tool0"/>
    <origin rpy="0 0 0" xyz="0 0 0"/>
  </joint>
  <joint name="irbp_a250" type="fixed">
    <parent link="world"/>
    <child link="irbp_a250/base_link"/>
    <origin rpy="-0.005599 -0.005742 1.550718" xyz="1.753 0.015 -0.003"/>
  </joint>
  <joint name="abb_robot" type="fixed">
    <parent link="world"/>
    <child link="base_link"/>
    <origin rpy="0 0 0" xyz="0 0 0.067"/>
  </joint>
  <!-- Table -->
  <link name="table0">
    <visual>
      <geometry>
        <mesh filename="package://aimen_workcell/meshes/table/table.stl"/>
      </geometry>
      <material name="gray">
        <color rgba="0.4 0.4 0.4 0.8"/>
      </material>
    </visual>
  </link>
  <joint name="table0" type="fixed">
    <parent link="irbp_a250/tool0"/>
    <child link="table0"/>
    <origin rpy="0 0 0" xyz="0 0 0"/>
    <axis xyz="0 0 1"/>
  </joint>
  <!-- Cell walls -->
  <link name="walls">
    <visual>
      <geometry>
        <mesh filename="package://aimen_workcell/meshes/cell/cell.stl"/>
      </geometry>
      <origin xyz="0 0 0"/>
      <material name="white">
        <color rgba="1 1 1 0.75"/>
      </material>
    </visual>
  </link>
  <joint name="walls" type="fixed">
    <parent link="world"/>
    <child link="walls"/>
    <origin xyz="0 0 0"/>
  </joint>
  <joint name="workcell" type="fixed">
    <parent link="world"/>
    <child link="base_link"/>
    <origin rpy="0 0 0" xyz="0 0 0.067"/>
  </joint>
  <!-- Head -->
  <link name="head0">
    <visual>
      <geometry>
        <mesh filename="package://proper_workcell/meshes/head/visual/head_wt03.stl"/>
      </geometry>
      <material name="dark_gray">
        <color rgba="0.3 0.4 0.3 1"/>
      </material>
    </visual>
    <collision>
      <geometry>
        <mesh filename="package://proper_workcell/meshes/head/collision/head_wt03.stl"/>
      </geometry>
      <material name="yellow">
        <color rgba="0 1 1 1"/>
      </material>
    </collision>
  </link>
  <joint name="head0" type="fixed">
    <parent link="tool0"/>
    <child link="head0"/>
    <origin rpy="0 0 1.570796327" xyz="0 0 0"/>
    <axis xyz="0 0 1"/>
  </joint>
  <!-- TCP -->
  <link name="tcp0"/>
  <joint name="tcp0" type="fixed">
    <parent link="tool0"/>
    <child link="tcp0"/>
    <origin rpy="3.141592654 -1.047197555 3.141592654" xyz="0.2462 -0.0203 0.4320"/>
    <axis xyz="0 0 1"/>
  </joint>
  <!-- Workobject -->
  <link name="workobject"/>
  <joint name="workobject" type="fixed">
    <parent link="base_link"/>
    <child link="workobject"/>
    <origin rpy="0 0 0" xyz="1.550 -0.178 0.9308"/>
  </joint>
  <!-- Camera -->
  <link name="camera0"/>
  <joint name="camera0" type="fixed">
    <parent link="tool0"/>
    <child link="camera0"/>
    <origin rpy="-1.148206 0.311297 -2.151468" xyz="0.0715 0.2219 0.3248"/>
  </joint>
</robot>

